<!-- ======================================================
        This file is part of MuJoCo.     
        Copyright 2009-2016 Roboti LLC.
        
        Model           :: arm_claw
                
        Mujoco          :: Advanced physics simulation engine
                Source          : www.roboti.us
                Version         : 1.31
                Released        : 23Apr16
                
        Author          :: Vikash Kumar
                Contacts        : kumar@roboti.us
                Last edits      : 30Apr16, 30Nov'15, 5Nov'15
====================================================== -->
<mujoco model="arm_claw (v1.31)">
        <compiler       inertiafromgeom="auto"
                                angle="radian"/>
                        
        <size   nuser_jnt="1"
                        nuser_geom="1"/>

        <option timestep="0.001"
                        gravity="0 0 -9.8"
                        viscosity="0"
                        iterations="20"
                        />
        
        <asset>
                <material name="MatGnd" specular=".3" shininess=".3" reflectance="0.0" rgba=".5 .55 .5 1"/>
        </asset>
        
        <default>
                <joint limited="true" damping="1" stiffness="0" armature=".1" user="0"/>
                <geom solref="0.1 100" solimp="0.95 0.95 0.01" margin="0.001" user="0" condim="4"/>
                <motor ctrllimited="true" ctrlrange="-1 1"/>
                <position ctrllimited="true"/>
                
                <default class='0'>
                        <geom friction="1 0.005 0.001" rgba=".75 .6 .5 1" contype="1" conaffinity="0"/>
                </default>

                <default class='1'>
                        <geom friction="1 0.005 0.001" rgba=".7 .6 .55 1" contype="1" conaffinity="0"/>
                </default>
                
                <default class='arm'>
                        <joint damping="5"/>
                </default>
        </default>

        <worldbody>
                <light directional="true" cutoff="40" exponent="10" diffuse=".4 .4 .4" specular=".7 .7 .7" pos="0 0 1.5" dir="0 0 -1"/>
                <geom solref="0.008 1" name="tableTop" material="MatGnd" type="plane" pos="0.15 0 0.15" size="0.8 0.8 0.5" rgba=".6 .6 .5 1" contype="1" conaffinity="1"/>
                                                                        
                <!--  ================= ARM ================= /-->
                <body name="upperarm" pos="0.05 0.1 0.6">
                        <geom class="0" type="capsule" fromto="0 0 0 0 0 -0.345" size="0.05"/>
                        <joint class='arm' name="s_abduction" type="hinge" pos="0 0 0" axis="1 0 0" range="-1.57 .7" limited='true' user="001"/>
			<joint class='arm' name="s_flexion" type="hinge" pos="0 0 0" axis="0 -1 0" range="-.85 1.57" limited='true' user="002"/>
			<joint class='arm' name="s_rotation" type="hinge" pos="0 0 0" axis="0 0 1" range="-.85 .85" limited='true' user="003"/>
                                        
                        <body name="forearm" pos="0 0 -0.36">
                                <geom class="0" type="capsule" fromto="0 0 0 0.225 0 0" size="0.035"/>
                                <joint class='arm' name="e_flexion" type="hinge" pos="0 0 0" axis="0 -1 0" range="-1.5 1.05" limited='true' user="004"/>
                                <site name="end_effector" pos="0.225 0 0" size="0.001"/>
                        </body>
                        
                </body>
                
                <!--  ================= OBJECT ================= /-->
                <body name="a_object" pos="0.05 0.1 0.2">
                        <geom density="5e4" type="box" name="a_box" pos="-0.1 -0.1 0" size="0.05 0.05 0.05" rgba="0.5 0.6 0.8 1" user="1" contype="0" conaffinity="1"/>
                        <joint name="a_obj" type="free" limited='false' damping="0" armature="0"/>
                </body>
                
                
        </worldbody>
        <contact>
                        <pair geom1="a_box" geom2="tableTop" solref = '0.008 1'/>
        </contact>
        <actuator>
        
                <!--  ================= Torque actuators ================= /-->
                <motor joint='s_abduction'      name='As_abduction' gear="100"/>
                <motor joint='s_flexion'        name='As_flexion'       gear="100"/>
                <motor joint='s_rotation'       name='As_rotation'      gear="100"/>
                <motor joint='e_flexion'        name='Ae_flexion'       gear="70"/>
<!--            <motor joint='rc_close'         name='Arc_close'        gear="10"/>
                <motor joint='lc_close'         name='Alc_close'        gear="10"/> -->
                
                <!--  ================= Position actuators ================= /-->
<!--            <position joint='s_abduction'   name='As_abduction' kp="100" ctrlrange='-1.57 .7'/>
                <position joint='s_flexion'     name='As_flexion'       kp="100" ctrlrange='-.85 1.57'/>
                <position joint='s_rotation'    name='As_rotation'      kp="100" ctrlrange='-.85 0.85'/>
                <position joint='e_flexion'     name='Ae_flexion'       kp="70"  ctrlrange='-1.5 1.05'/>
                <position joint='e_pronation'   name='Ae_pronation' kp="70"  ctrlrange='-1.5 1.57'/>
                <position joint='w_abduction'   name='Aw_abduction' kp="30"  ctrlrange='-0.5 0.5'/>
                <position joint='w_flexion'     name='Aw_flexion'       kp="30"  ctrlrange='-1.05 1.05'/>
                <position joint='rc_close'              name='Arc_close'        kp="10"  ctrlrange='-1.05 1.05'/>
                <position joint='lc_close'              name='Alc_close'        kp="10"  ctrlrange='-1.05 1.05'/> -->

        </actuator>

</mujoco>
